<?xml version="1.0"?>

<robot name="scara" xmlns:xacro="http://ros.org/wiki/xacro">
  <link name="base_link">
    <visual>
      <geometry>
        <cylinder length="0.025" radius="1"/>
      </geometry>
    </visual>
    <collision>
      <geometry>
        <cylinder length="0.025" radius="1"/>
      </geometry>
    </collision>
  </link>

  <transmission name="base_link_trans">
    <type>transmission_interface/SimpleTransmission</type>
    <actuator name="$base_link_actuator">
      <mechanicalReduction>1</mechanicalReduction>
    </actuator>
    <joint name="base_to_L1">
      <hardwareInterface>PositionJointInterface</hardwareInterface>
    </joint>
  </transmission>

  <link name="L1">
    <visual>
      <geometry>
        <cylinder length="1" radius="0.025"/>
      </geometry>
      <origin rpy="0 0 0" xyz="0 0 0.025"/>
    </visual>
    <collision>
      <geometry>
        <cylinder length="1" radius="0.025"/>
      </geometry>
    </collision>
  </link>

  <transmission name="l1_trans">
    <type>transmission_interface/SimpleTransmission</type>
    <actuator name="$link1_transmission">
      <mechanicalReduction>1</mechanicalReduction>
    </actuator>
    <joint name="l1_to_l2">
      <hardwareInterface>PositionJointInterface</hardwareInterface>
    </joint>
  </transmission>

  <link name="L2">
    <visual>
      <geometry>
        <cylinder length="1" radius="0.025"/>
      </geometry>
      <origin rpy="0 0 0" xyz="0 0 1.025"/>
    </visual>
    <collision>
      <geometry>
        <cylinder length="1" radius="0.025"/>
      </geometry>
    </collision>
  </link>

  <link name="L3">
    <visual>
      <geometry>
        <box size="1 1 1"/>
      </geometry>
      <origin rpy="0 0 0" xyz="0 0 2.025"/>
    </visual>
    <collision>
      <geometry>
        <box size="1 1 1"/>
      </geometry>
    </collision>
  </link>

  <link name="end_effector">
    <visual>
      <geometry>
        <box size=".01 1 1"/>
      </geometry>
      <origin rpy="0 0 0" xyz="0.25 0 2.025"/>
    </visual>
    <collision>
      <geometry>
        <box size="0.01 1 1"/>
      </geometry>
    </collision>
  </link>

  <joint name="base_to_L1" type="revolute">
    <parent link="base_link"/>
    <child link="L1"/>
    <axis xyz="0 0 1"/>
    <origin xyz="0 0 0.025"/>
  </joint>

  <joint name="L1_to_L2" type="revolute">
    <parent link="L1"/>
    <child link="L1"/>
    <axis xyz="1 0 0"/>
    <origin rpy="1.5707 0 0" xyz="0 0 1.025"/>
  </joint>

  <joint name="L2_to_L3" type="fixed">
    <parent link="L2"/>
    <child link="L3"/>
    <origin rpy="0 0 0" xyz="0 0 2.025"/>
  </joint>

  <gazebo>
    <plugin name="gazebo_ros_control" filename="libgazebo_ros_control.so">
      <robotNamespace>/</robotNamespace>
    </plugin>
  </gazebo>
</robot>
